<?xml version="1.0" ?>
<!-- =================================================================================== -->
<!-- |    This document was autogenerated by xacro from model.xacro                    | -->
<!-- |    EDITING THIS FILE BY HAND IS NOT RECOMMENDED                                 | -->
<!-- =================================================================================== -->
<robot name="HolonomicUrdf">
  <link name="base_footprint"/>
  <link name="base_link">
    <inertial>
      <mass value="100"/>
      <origin rpy="0 0 0" xyz="0 0 0"/>
      <inertia ixx="10.416666666666668" ixy="0.0" ixz="0.0" iyy="10.416666666666668" iyz="0.0" izz="16.666666666666668"/>
    </inertial>
    <visual>
      <geometry>
        <box size="1.0 1.0 0.5"/>
      </geometry>
      <material name="blue">
        <color rgba="0.0 0.0 1.0 1.0"/>
      </material>
    </visual>
  </link>
  <joint name="base_joint" type="fixed">
    <parent link="base_footprint"/>
    <child link="base_link"/>
  </joint>
  <link name="wheel_base_link">
    <inertial>
      <mass value="0.01"/>
      <origin rpy="0 0 0" xyz="0 0 0"/>
      <inertia ixx="233333.33333333334" ixy="0.0" ixz="0.0" iyy="233333.33333333334" iyz="0.0" izz="450000.0"/>
    </inertial>
    <visual>
      <geometry>
        <cylinder length="0.1" radius="0.3"/>
      </geometry>
      <material name="red">
        <color rgba="1.0 0.0 0.0 1.0"/>
      </material>
    </visual>
  </link>
  <joint name="wheel_base_joint" type="continuous">
    <parent link="base_link"/>
    <child link="wheel_base_link"/>
    <origin rpy="0 0 0" xyz="0 0 0"/>
    <axis xyz="0 0 1"/>
  </joint>
  <link name="wheel_link">
    <inertial>
      <mass value="1e-07"/>
      <origin rpy="0 0 0" xyz="0 0 0"/>
      <inertia ixx="1.0000083333333336" ixy="0.0" ixz="0.0" iyy="1.0000083333333336" iyz="0.0" izz="2.0000000000000004"/>
    </inertial>
    <visual>
      <geometry>
        <cylinder length="0.001" radius="0.2"/>
      </geometry>
      <material name="red">
        <color rgba="1.0 0.0 0.0 1.0"/>
      </material>
    </visual>
    <collision>
      <geometry>
        <cylinder length="0.001" radius="0.2"/>
      </geometry>
      <origin rpy="0 0 0" xyz="0 0 0"/>
    </collision>
  </link>
  <joint name="wheel_joint" type="continuous">
    <parent link="wheel_base_link"/>
    <child link="wheel_link"/>
    <origin rpy="-1.57 0 0" xyz="0 0 -0.1"/>
    <axis xyz="0 0 1"/>
  </joint>
  <link name="caster1_link">
    <inertial>
      <mass value="0.3"/>
      <origin rpy="0 0 0" xyz="0 0 0"/>
      <inertia ixx="3000000.0" ixy="0.0" ixz="0.0" iyy="3000000.0" iyz="0.0" izz="3000000.0"/>
    </inertial>
    <visual>
      <geometry>
        <sphere radius="0.05"/>
      </geometry>
      <material name="green">
        <color rgba="0.0 1.0 0.0 1.0"/>
      </material>
    </visual>
    <collision>
      <geometry>
        <sphere radius="0.05"/>
      </geometry>
      <origin rpy="0 0 0" xyz="0 0 0"/>
    </collision>
  </link>
  <joint name="caster1_joint" type="fixed">
    <origin rpy="0 0 0" xyz="0.5000000000000001 0.5000000000000001 -0.25"/>
    <parent link="base_link"/>
    <child link="caster1_link"/>
  </joint>
  <link name="caster2_link">
    <inertial>
      <mass value="0.3"/>
      <origin rpy="0 0 0" xyz="0 0 0"/>
      <inertia ixx="3000000.0" ixy="0.0" ixz="0.0" iyy="3000000.0" iyz="0.0" izz="3000000.0"/>
    </inertial>
    <visual>
      <geometry>
        <sphere radius="0.05"/>
      </geometry>
      <material name="green">
        <color rgba="0.0 1.0 0.0 1.0"/>
      </material>
    </visual>
    <collision>
      <geometry>
        <sphere radius="0.05"/>
      </geometry>
      <origin rpy="0 0 0" xyz="0 0 0"/>
    </collision>
  </link>
  <joint name="caster2_joint" type="fixed">
    <origin rpy="0 0 0" xyz="-0.5000000000000001 0.5000000000000001 -0.25"/>
    <parent link="base_link"/>
    <child link="caster2_link"/>
  </joint>
  <link name="caster3_link">
    <inertial>
      <mass value="0.3"/>
      <origin rpy="0 0 0" xyz="0 0 0"/>
      <inertia ixx="3000000.0" ixy="0.0" ixz="0.0" iyy="3000000.0" iyz="0.0" izz="3000000.0"/>
    </inertial>
    <visual>
      <geometry>
        <sphere radius="0.05"/>
      </geometry>
      <material name="green">
        <color rgba="0.0 1.0 0.0 1.0"/>
      </material>
    </visual>
    <collision>
      <geometry>
        <sphere radius="0.05"/>
      </geometry>
      <origin rpy="0 0 0" xyz="0 0 0"/>
    </collision>
  </link>
  <joint name="caster3_joint" type="fixed">
    <origin rpy="0 0 0" xyz="-0.5000000000000001 -0.5000000000000001 -0.25"/>
    <parent link="base_link"/>
    <child link="caster3_link"/>
  </joint>
  <link name="caster4_link">
    <inertial>
      <mass value="0.3"/>
      <origin rpy="0 0 0" xyz="0 0 0"/>
      <inertia ixx="3000000.0" ixy="0.0" ixz="0.0" iyy="3000000.0" iyz="0.0" izz="3000000.0"/>
    </inertial>
    <visual>
      <geometry>
        <sphere radius="0.05"/>
      </geometry>
      <material name="green">
        <color rgba="0.0 1.0 0.0 1.0"/>
      </material>
    </visual>
    <collision>
      <geometry>
        <sphere radius="0.05"/>
      </geometry>
      <origin rpy="0 0 0" xyz="0 0 0"/>
    </collision>
  </link>
  <joint name="caster4_joint" type="fixed">
    <origin rpy="0 0 0" xyz="0.5000000000000001 -0.5000000000000001 -0.25"/>
    <parent link="base_link"/>
    <child link="caster4_link"/>
  </joint>
  <link name="base_lidar_link">
    <inertial>
      <mass value="0.01"/>
      <origin rpy="0 0 0" xyz="0 0 0"/>
      <inertia ixx="1.4583333333333337e-05" ixy="0.0" ixz="0.0" iyy="1.4583333333333337e-05" iyz="0.0" izz="1.2500000000000002e-05"/>
    </inertial>
    <visual>
      <geometry>
        <cylinder length="0.1" radius="0.05"/>
      </geometry>
      <material name="red">
        <color rgba="1.0 0.0 0.0 1.0"/>
      </material>
    </visual>
  </link>
  <gazebo reference="base_lidar">
    <sensor name="base" type="ray">
      <pose>0 0 0 0 0 0</pose>
      <visualize>true</visualize>
      <update_rate>10</update_rate>
      <ray>
        <scan>
          <horizontal>
            <samples>400</samples>
            <resolution>1</resolution>
            <min_angle>-1.5707963267948966</min_angle>
            <max_angle>1.5707963267948966</max_angle>
          </horizontal>
        </scan>
        <range>
          <min>0.10</min>
          <max>20.0</max>
          <resolution>0.01</resolution>
        </range>
        <noise>
          <type>gaussian</type>
          <mean>0.0</mean>
          <stddev>0.01</stddev>
        </noise>
      </ray>
      <plugin filename="libgazebo_ros_laser.so" name="gazebo_ros_lidar_controller">
        <topicName>/base_link/scan</topicName>
        <frameName>base_link</frameName>
      </plugin>
    </sensor>
  </gazebo>
  <joint name="base_joint" type="fixed">
    <parent link="base_link"/>
    <child link="base_lidar"/>
    <origin rpy="0 0 0" xyz="0 0 0.5"/>
  </joint>
  <gazebo>
    <!-- Global odometer -->
    <plugin filename="ignition-gazebo-odometry-publisher-system" name="ignition::gazebo::systems::OdometryPublisher">
      <odom_publish_frequency>50</odom_publish_frequency>
      <odom_topic>/odom</odom_topic>
      <odom_frame>odom</odom_frame>
      <robot_base_frame>base_footprint</robot_base_frame>
      <tf_topic>/odom/tf</tf_topic>
    </plugin>
    <!-- Joint state publisher -->
    <plugin filename="libignition-gazebo-joint-state-publisher-system.so" name="ignition::gazebo::systems::JointStatePublisher">
      <topic>joint_states</topic>
    </plugin>
    <plugin filename="libHolonomicPlugin.so" name="holonomic_sim::HolonomicPlugin">
      <wheel_joint>wheel_joint</wheel_joint>
      <base_joint>wheel_base_joint</base_joint>
    </plugin>
  </gazebo>
</robot>
