
<robot name="HolonomicUrdf">

    <link name="base_footprint"/>

    <link name="base_link">
        <inertial>
            <mass value="1.0"/>
            <origin xyz="0 0 0" rpy="0 0 0"/>
            <inertia ixx="0.1" ixy="0.0" ixz="0.0" iyy="0.1" iyz="0.0" izz="0.1"/>
        </inertial>
        <visual>
            <geometry>
                <box size="1 1 0.5"/>
            </geometry>
            <origin xyz="0 0 0" rpy="0 0 0"/>
            <material name="blue">
            <color rgba="0.0 0.0 1.0 1.0"/>
            </material>
        </visual>
        <collision>
            <geometry>
                <box size="1 1 0.5"/>
            </geometry>
            <origin xyz="0 0 0" rpy="0 0 0"/>
        </collision>
    </link>

    <joint name="base_joint" type="fixed">
        <parent link="base_footprint"/>
        <child  link="base_link"/>
    </joint>

    <link name="wheel_base">
        <inertial>
            <mass value="1.0"/>
            <origin xyz="0 0 0" rpy="0 0 0"/>
            <inertia ixx="0.1" ixy="0.0" ixz="0.0" iyy="0.1" iyz="0.0" izz="0.1"/>
        </inertial>
        <visual>
            <geometry>
                <cylinder length="0.1" radius="0.3"/>
            </geometry>
            <origin xyz="0 0 0" rpy="0 0 0"/>
            <material name="red">
            <color rgba="1.0 0.0 0.0 1.0"/>
            </material>
        </visual>
    </link>

    <joint name="wheel_base_joint" type="continuous">
        <parent link="base_link"/>
        <child  link="wheel_base"/>

        <origin xyz="0 0 0.3" rpy="0 0 0"/>
        <axis xyz="0 0 1"/>
    </joint>

    <link name="wheel">
        <inertial>
            <mass value="1.0"/>
            <origin xyz="0 0 0" rpy="-1.57 0 0"/>
            <inertia ixx="0.1" ixy="0.0" ixz="0.0" iyy="0.1" iyz="0.0" izz="0.1"/>
        </inertial>
        <visual>
            <geometry>
                <cylinder length="0.1" radius="0.3"/>
            </geometry>
            <origin xyz="0 0 0" rpy="-1.57 0 0"/>
            <material name="red">
            <color rgba="1.0 0.0 0.0 1.0"/>
            </material>
        </visual>
    </link>

    <joint name="wheel_joint" type="continuous">
        <parent link="wheel_base"/>
        <child  link="wheel"/>

        <origin xyz="0 0 -0.3" rpy="0 0 0"/>
        <axis xyz="0 0 1"/>
    </joint>

    <link name="caster_FR">
        <inertial>
            <mass value="1.0"/>
            <origin xyz="0 0 0" rpy="0 0 0"/>
            <inertia ixx="0.1" ixy="0.0" ixz="0.0" iyy="0.1" iyz="0.0" izz="0.1"/>
        </inertial>
        <visual>
            <geometry>
                <sphere radius="0.3"/>
            </geometry>
            <origin xyz="0 0 0" rpy="0 0 0"/>
            <material name="green">
            <color rgba="0.0 1.0 0.0 1.0"/>
            </material>
        </visual>
    </link>

    <joint name="caster_FR_joint" type="fixed">
        <parent link="base_link"/>
        <child  link="caster_FR"/>

        <origin xyz="0.5 0.5 0" rpy="0 0 0"/>
    </joint>

    <link name="caster_FL">
        <inertial>
            <mass value="1.0"/>
            <origin xyz="0 0 0" rpy="0 0 0"/>
            <inertia ixx="0.1" ixy="0.0" ixz="0.0" iyy="0.1" iyz="0.0" izz="0.1"/>
        </inertial>
        <visual>
            <geometry>
                <sphere radius="0.3"/>
            </geometry>
            <origin xyz="0 0 0" rpy="0 0 0"/>
            <material name="green">
            <color rgba="0.0 1.0 0.0 1.0"/>
            </material>
        </visual>
    </link>

    <joint name="caster_FL_joint" type="fixed">
        <parent link="base_link"/>
        <child  link="caster_FL"/>

        <origin xyz="0.5 -0.5 0" rpy="0 0 0"/>
    </joint>

    <link name="caster_BR">
        <inertial>
            <mass value="1.0"/>
            <origin xyz="0 0 0" rpy="0 0 0"/>
            <inertia ixx="0.1" ixy="0.0" ixz="0.0" iyy="0.1" iyz="0.0" izz="0.1"/>
        </inertial>
        <visual>
            <geometry>
                <sphere radius="0.3"/>
            </geometry>
            <origin xyz="0 0 0" rpy="0 0 0"/>
            <material name="green">
            <color rgba="0.0 1.0 0.0 1.0"/>
            </material>
        </visual>
    </link>

    <joint name="caster_BR_joint" type="fixed">
        <parent link="base_link"/>
        <child  link="caster_BR"/>

        <origin xyz="-0.5 0.5 0" rpy="0 0 0"/>
    </joint>

    <link name="caster_BL">
        <inertial>
            <mass value="1.0"/>
            <origin xyz="0 0 0" rpy="0 0 0"/>
            <inertia ixx="0.1" ixy="0.0" ixz="0.0" iyy="0.1" iyz="0.0" izz="0.1"/>
        </inertial>
        <visual>
            <geometry>
                <sphere radius="0.3"/>
            </geometry>
            <origin xyz="0 0 0" rpy="0 0 0"/>
            <material name="green">
            <color rgba="0.0 1.0 0.0 1.0"/>
            </material>
        </visual>
    </link>

    <joint name="caster_BL_joint" type="fixed">
        <parent link="base_link"/>
        <child  link="caster_BL"/>

        <origin xyz="-0.5 -0.5 0" rpy="0 0 0"/>
    </joint>
    
</robot>